<?xml version="1.0" ?>
<!-- =================================================================================== -->
<!-- |    This document was autogenerated by xacro from src/jackrobot_moveit_config/config/arm_manipulator.urdf.xacro | -->
<!-- |    EDITING THIS FILE BY HAND IS NOT RECOMMENDED                                 | -->
<!-- =================================================================================== -->
<robot name="arm_manipulator">
  <material name="robot_red">
    <color rgba="0.8 0.1 0.1 1.0"/>
  </material>
  <material name="robot_white">
    <color rgba="0.9 0.9 0.9 1.0"/>
  </material>
  <material name="robot_grey">
    <color rgba="0.3 0.3 0.3 1.0"/>
  </material>
  <link name="base_link"/>
  <joint name="base_joint" type="fixed">
    <parent link="base_link"/>
    <child link="arm_base_link"/>
    <origin rpy="0 0 0" xyz="0 0 0"/>
  </joint>
  <link name="arm_base_link">
    <visual>
      <origin rpy="0 0 0" xyz="0 0 0.05"/>
      <geometry>
        <cylinder length="0.1" radius="0.1"/>
      </geometry>
      <material name="robot_grey"/>
    </visual>
    <collision>
      <origin rpy="0 0 0" xyz="0 0 0.05"/>
      <geometry>
        <cylinder length="0.1" radius="0.1"/>
      </geometry>
    </collision>
    <inertial>
      <origin rpy="0 0 0" xyz="0 0 0.05"/>
      <mass value="2.0"/>
      <inertia ixx="0.006667" ixy="0.0" ixz="0.0" iyy="0.006667" iyz="0.0" izz="0.01"/>
    </inertial>
  </link>
  <joint name="arm_0_joint" type="revolute">
    <parent link="arm_base_link"/>
    <child link="link_1"/>
    <origin rpy="0 0 0" xyz="0 0 0.1"/>
    <axis xyz="0 0 1"/>
    <limit effort="10.0" lower="-3.1416" upper="3.1416" velocity="1.5"/>
  </joint>
  <link name="link_1">
    <visual>
      <origin rpy="0 0 0" xyz="0 0 0.15"/>
      <geometry>
        <cylinder length="0.3" radius="0.04"/>
      </geometry>
      <material name="robot_white"/>
    </visual>
    <collision>
      <origin rpy="0 0 0" xyz="0 0 0.15"/>
      <geometry>
        <cylinder length="0.3" radius="0.04"/>
      </geometry>
    </collision>
    <inertial>
      <origin rpy="0 0 0" xyz="0 0 0.15"/>
      <mass value="1.0"/>
      <inertia ixx="0.0079" ixy="0.0" ixz="0.0" iyy="0.0079" iyz="0.0" izz="0.0008"/>
    </inertial>
  </link>
  <joint name="arm_1_joint" type="revolute">
    <parent link="link_1"/>
    <child link="link_2"/>
    <origin rpy="0 0 0" xyz="0 0 0.3"/>
    <axis xyz="0 1 0"/>
    <limit effort="10.0" lower="-1.5708" upper="1.5708" velocity="1.5"/>
  </joint>
  <link name="link_2">
    <visual>
      <origin rpy="0 0 0" xyz="0 0 0.15"/>
      <geometry>
        <cylinder length="0.3" radius="0.035"/>
      </geometry>
      <material name="robot_red"/>
    </visual>
    <collision>
      <origin rpy="0 0 0" xyz="0 0 0.15"/>
      <geometry>
        <cylinder length="0.3" radius="0.035"/>
      </geometry>
    </collision>
    <inertial>
      <origin rpy="0 0 0" xyz="0 0 0.15"/>
      <mass value="0.8"/>
      <inertia ixx="0.00624" ixy="0.0" ixz="0.0" iyy="0.00624" iyz="0.0" izz="0.00049"/>
    </inertial>
  </link>
  <joint name="arm_2_joint" type="revolute">
    <parent link="link_2"/>
    <child link="link_3"/>
    <origin rpy="0 0 0" xyz="0 0 0.3"/>
    <axis xyz="0 1 0"/>
    <limit effort="10.0" lower="-2.0944" upper="2.0944" velocity="1.5"/>
  </joint>
  <link name="link_3">
    <visual>
      <origin rpy="0 0 0" xyz="0 0 0.1"/>
      <geometry>
        <cylinder length="0.2" radius="0.03"/>
      </geometry>
      <material name="robot_white"/>
    </visual>
    <collision>
      <origin rpy="0 0 0" xyz="0 0 0.1"/>
      <geometry>
        <cylinder length="0.2" radius="0.03"/>
      </geometry>
    </collision>
    <inertial>
      <origin rpy="0 0 0" xyz="0 0 0.1"/>
      <mass value="0.5"/>
      <inertia ixx="0.00178" ixy="0.0" ixz="0.0" iyy="0.00178" iyz="0.0" izz="0.00023"/>
    </inertial>
  </link>
  <joint name="gripper_base_joint" type="fixed">
    <parent link="link_3"/>
    <child link="gripper_base_link"/>
    <origin rpy="0 0 0" xyz="0 0 0.2"/>
  </joint>
  <link name="gripper_base_link">
    <visual>
      <origin rpy="0 0 0" xyz="0 0 0.01"/>
      <geometry>
        <box size="0.03 0.12 0.02"/>
      </geometry>
      <material name="robot_grey"/>
    </visual>
    <collision>
      <origin rpy="0 0 0" xyz="0 0 0.01"/>
      <geometry>
        <box size="0.03 0.12 0.02"/>
      </geometry>
    </collision>
    <inertial>
      <origin rpy="0 0 0" xyz="0 0 0.01"/>
      <mass value="0.2"/>
      <inertia ixx="0.000247" ixy="0.0" ixz="0.0" iyy="0.000022" iyz="0.0" izz="0.000255"/>
    </inertial>
  </link>
  <joint name="gripper_1_joint" type="prismatic">
    <parent link="gripper_base_link"/>
    <child link="gripper_finger_1"/>
    <origin rpy="0 0 0" xyz="0 0.04 0.02"/>
    <axis xyz="0 1 0"/>
    <limit effort="5.0" lower="-0.03" upper="0.0" velocity="0.1"/>
  </joint>
  <link name="gripper_finger_1">
    <visual>
      <origin rpy="0 0 0" xyz="0 0 0.025"/>
      <geometry>
        <box size="0.02 0.01 0.05"/>
      </geometry>
      <material name="robot_red"/>
    </visual>
    <collision>
      <origin rpy="0 0 0" xyz="0 0 0.025"/>
      <geometry>
        <box size="0.02 0.01 0.05"/>
      </geometry>
    </collision>
    <inertial>
      <origin rpy="0 0 0" xyz="0 0 0.025"/>
      <mass value="0.05"/>
      <inertia ixx="0.000011" ixy="0.0" ixz="0.0" iyy="0.000012" iyz="0.0" izz="0.000002"/>
    </inertial>
  </link>
  <joint name="gripper_2_joint" type="prismatic">
    <parent link="gripper_base_link"/>
    <child link="gripper_finger_2"/>
    <origin rpy="0 0 0" xyz="0 -0.04 0.02"/>
    <axis xyz="0 -1 0"/>
    <limit effort="5.0" lower="-0.03" upper="0.0" velocity="0.1"/>
  </joint>
  <link name="gripper_finger_2">
    <visual>
      <origin rpy="0 0 0" xyz="0 0 0.025"/>
      <geometry>
        <box size="0.02 0.01 0.05"/>
      </geometry>
      <material name="robot_red"/>
    </visual>
    <collision>
      <origin rpy="0 0 0" xyz="0 0 0.025"/>
      <geometry>
        <box size="0.02 0.01 0.05"/>
      </geometry>
    </collision>
    <inertial>
      <origin rpy="0 0 0" xyz="0 0 0.025"/>
      <mass value="0.05"/>
      <inertia ixx="0.000011" ixy="0.0" ixz="0.0" iyy="0.000012" iyz="0.0" izz="0.000002"/>
    </inertial>
  </link>
  <ros2_control name="FakeSystem" type="system">
    <hardware>
      <!-- By default, set up controllers for simulation. This won't work on real hardware -->
      <plugin>gz_ros2_control/GazeboSimSystem</plugin>
    </hardware>
    <joint name="arm_0_joint">
      <command_interface name="position"/>
      <state_interface name="position">
        <param name="initial_value">0</param>
      </state_interface>
      <state_interface name="velocity"/>
    </joint>
    <joint name="arm_1_joint">
      <command_interface name="position"/>
      <state_interface name="position">
        <param name="initial_value">0</param>
      </state_interface>
      <state_interface name="velocity"/>
    </joint>
    <joint name="arm_2_joint">
      <command_interface name="position"/>
      <state_interface name="position">
        <param name="initial_value">0</param>
      </state_interface>
      <state_interface name="velocity"/>
    </joint>
    <joint name="gripper_1_joint">
      <command_interface name="position"/>
      <state_interface name="position">
        <param name="initial_value">0</param>
      </state_interface>
      <state_interface name="velocity"/>
    </joint>
    <joint name="gripper_2_joint">
      <command_interface name="position"/>
      <state_interface name="position">
        <param name="initial_value">0</param>
      </state_interface>
      <state_interface name="velocity"/>
    </joint>
  </ros2_control>
  <gazebo>
    <plugin filename="libgz_ros2_control-system.so" name="gz_ros2_control::GazeboSimROS2ControlPlugin">
      <parameters>/home/user/ros2_ws/install/jackrobot_moveit_config/share/jackrobot_moveit_config/config/ros2_controllers.yaml</parameters>
      <controller_manager_name>controller_manager</controller_manager_name>
    </plugin>
  </gazebo>
</robot>
